Workbook
Name Acct_Codes: '[1]Exp-Codes'!$C$3:$C$22
Name emma1: #REF!
Name KeyCustom1: [2]January!$N$2
Name KeyCustom2: [2]January!$R$2
Name KeyPersonal: [2]January!$G$2
Name KeySick: [2]January!$K$2
Name KeyVacation: [2]January!$C$2
Name simt1: #REF!
Name sunche: #REF!
Name sunche1: #REF!

Sheet fuel capture
B1: =IF(A1="","",VLOOKUP(A1,'IHS DATABASE'!C:D,2,0)) | AJ1: =SUBTOTAL(9,AJ3:AJ496903) -> 4300 | BD1: =SUBTOTAL(9,BD2:BD2) -> 0 | BF1: VALIDATION STATUS
A2: SITE ID | B2: SITE NAME | C2: SBC | D2: NAME OF TECHNICIAN | E2: REGION | F2: REGION MANAGER | G2: QUALITY AUDITOR | H2: SECURITY (YES/NO) | I2: INDOOR / OUTDOOR | J2: POWER TOPOLOGY | K2: CURRENT TOPOLOGY | L2: REASONS OF POWER TOPOLOGY CHANGE | M2: SITE TYPE | N2: ORDER NUMBERS | O2: CURRENT VISIT DATE | P2: PREVIOUS VISIT DATE | Q2: TYPE OF VISIT | R2: DG SERIAL NUMBER | S2: DG BRAND | T2: AC / DC | U2: DG KVA | V2: DG REPLACEMENT DATE | W2: PREVIOUS DG RUN HOURS | X2: CURRENT DG RUN HOURS | Y2: RUNING HOURS | Z2: MAX RH | AA2: RH TEST | AB2: Last servicing | AC2: CURRENT SERVICING | AD2: NEXT SERVICE PLANED | AE2: DG serviced Hour | AF2: PREVIOUS DIESEL LEVEL | AG2: DG DIMENSION | AH2: FUEL FOUND IN CM | AI2: FUEL FOUND | AJ2: FUEL ADDED | AK2: FUEL LEFT ON SITE | AL2: FUEL CONSUMED | AM2: CPH | AN2: Manufacturer CPH | AO2: CPH Test | AP2: ZESCO METER S/NO | AQ2: PHASE TYPE | AR2: CURRENT GRID METER READING | AS2: PREVIOUS GRID METER READING | AT2: GRID CONSUMPTION (kWh) | AU2: N-PH1 VOLTAGE | AV2: N-PH2 VOLTAGE | AW2: N-PH3 VOLTAGE | AX2: LOAD 1 (A) | AY2: LOAD 2 (A) | AZ2: LOAD 3 (A) | BA2: DC LOAD (A) | BB2: COMMENT | BC2: SUPPLIER | BE2: NOC CAPTURED
A3: IHS_CBT_017M | B3: Overspill | C3: GNM | D3: KAMBOLE | E3: Copperbelt | F3: Mwenya Banda | G3: Elvis Mumba | I3: Outdoor | J3: Grid-Gen | M3: Green Field | O3: 46030 | P3: 46018 | S3: Falcon | U3: 20 | W3: 10174 | X3: 10225 | Y3: 51 | Z3: 288 | AA3: OK | AF3: 396 | AI3: 243 | AJ3: 50 | AK3: 293 | AL3: 153 | AM3: 3 | AN3: 2.5 | AT3: 0 | BB3: NORMAL CPH | BC3: SAHARA | BE3: CAPTURED
A4: IHS_CBT_031M | B4: Kawama | C4: GNM | D4: KAMBOLE | E4: Copperbelt | F4: Mwenya Banda | G4: Elvis Mumba | I4: Indoor | J4: Grid-Gen | M4: Green Field | O4: 46030 | P4: 46029 | S4: GL Yanmar | U4: 20 | W4: 2044 | X4: 2045 | Y4: 1 | Z4: 24 | AA4: OK | AF4: 168 | AI4: 163 | AJ4: 250 | AK4: 413 | AL4: 5 | AM4: 5 | AN4: 2 | AT4: 0 | BB4: NORMAL CPH | BC4: SAHARA | BE4: CAPTURED
A5: IHS_CBT_025M | B5: Pamozi Extension | C5: GNM | D5: KAMBOLE | E5: Copperbelt | F5: Mwenya Banda | G5: Elvis Mumba | I5: Indoor | J5: Grid-Gen | M5: Green Field | O5: 46030 | P5: 46029 | S5: GL Yanmar | U5: 16 | W5: 4588 | X5: 4609 | Y5: 21 | Z5: 24 | AA5: OK | AF5: 110 | AI5: 47 | AJ5: 200 | AK5: 247 | AL5: 63 | AM5: 3 | AN5: 2 | AT5: 0 | BB5: NORMAL CPH | BC5: SAHARA | BE5: CAPTURED
A6: IHS_CBT_043M | B6: Fisenge | C6: GNM | D6: ISAAC | E6: Copperbelt | F6: Mwenya Banda | G6: Neddy Chiwasa | I6: Indoor | J6: Grid-Gen | M6: Green Field | O6: 46030 | P6: 46004 | S6: Gen Logic | U6: 16 | W6: faulty Controller | X6: Faulty Controller | Y6: #VALUE! | Z6: 624 | AA6: #VALUE! | AF6: 647 | AI6: 127 | AJ6: 200 | AK6: 327 | AL6: 520 | AM6: #VALUE! | AN6: 2 | AT6: 0 | BB6: FAULTY CONTROLLER | BC6: PUMA | BE6: CAPTURED
A7: IHS_CBT_056M | B7: Masangano | C7: GNM | D7: ROYD | E7: Copperbelt | F7: Mwenya Banda | G7: Elvis Mumba | I7: Indoor | J7: Grid-Gen | M7: Green Field | O7: 46030 | P7: 46361 | S7: GL Yanmar | U7: 16 | W7: Faulty Controller | X7: Faulty Controller | Y7: #VALUE! | Z7: -7944 | AA7: #VALUE! | AF7: 115 | AI7: 20 | AJ7: 200 | AK7: 220 | AL7: 95 | AM7: #VALUE! | AN7: 2 | AT7: 0 | BB7: FAULTY CONTROLLER | BC7: SAHARA | BE7: CAPTURED
A8: IHS_CBT_060M | B8: Kansafu | C8: GNM | D8: ROYD | E8: Copperbelt | F8: Mwenya Banda | G8: Elvis Mumba | I8: Indoor | J8: Grid-Gen | M8: Green Field | O8: 46030 | P8: 46022 | S8: Falcon | U8: 16 | W8: 2747 | X8: 2888 | Y8: 141 | Z8: 192 | AA8: OK | AF8: 493 | AI8: 70 | AJ8: 200 | AK8: 270 | AL8: 423 | AM8: 3 | AN8: 2 | AT8: 0 | BB8: NORMAL CPH | BC8: SAHARA | BE8: CAPTURED
A9: IHS_CBT_134M | B9: Kalulushi East | C9: GNM | D9: SAMUEL | E9: Copperbelt | F9: Mwenya Banda | G9: Chrispin Lindundu | I9: Outdoor | J9: Grid-Gen | M9: Green Field | O9: 46030 | P9: 46026 | S9: CK Works | U9: 20 | W9: 9634 | X9: 9657 | Y9: =X9-W9 -> 23 | Z9: =(O9-P9)*24 -> 96 | AA9: =IF(Y9>Z9,"inconsitent RH","OK") -> OK | AF9: 113 | AI9: 14 | AJ9: 100 | AK9: =AJ9+AI9 -> 114 | AL9: =AF9-AI9 -> 99 | AM9: =AL9/Y9 -> 4.3043478 | AN9: 2.5 | AT9: 0 | BB9: NORMAL CPH | BC9: SAHARA | BE9: CAPTURED
A10: IHS_CBT_251A | B10: Kitwe Railways | C10: GNM | D10: FACKSON | E10: Copperbelt | F10: Mwenya Banda | G10: Chrispin Lindundu | I10: Indoor | J10: Grid-Gen | M10: Green Field | O10: 46030 | P10: 46025 | S10: MPI | U10: 20 | W10: 0 | X10: 5 | Y10: 5 | Z10: 120 | AA10: OK | AF10: 160 | AI10: 138 | AJ10: 100 | AK10: 238 | AL10: 22 | AM10: 4.4 | AN10: 2.5 | AT10: 0 | BB10: NORMAL CPH | BC10: SAHARA | BE10: CAPTURED
A11: IHS_CBT_073M | B11: Cedrics Farm | C11: GNM | D11: FACKSON | E11: Copperbelt | F11: Mwenya Banda | G11: Chrispin Lindundu | I11: Outdoor | J11: Grid-Gen | M11: Green Field | O11: 46030 | P11: 46029 | S11: perkins | U11: 15 | W11: 18851 | X11: 18869 | Y11: =X11-W11 -> 18 | Z11: 24 | AA11: OK | AF11: 125 | AI11: 67 | AJ11: 200 | AK11: 267 | AL11: 58 | AM11: 3.2222222 | AN11: 1.8 | AT11: 0 | BB11: NORMAL CPH | BC11: SAHARA | BE11: CAPTURED
A12: IHS_CBT_081M | B12: Chamboli | C12: GNM | D12: FACKSON | E12: Copperbelt | F12: Mwenya Banda | G12: Chrispin Lindundu | I12: Indoor | J12: Grid-Gen | M12: Green Field | O12: 46030 | P12: 46029 | S12: Gen Logic | U12: 16 | W12: 19475 | X12: 19493 | Y12: 18 | Z12: 24 | AA12: OK | AF12: 152 | AI12: 105 | AJ12: 150 | AK12: 255 | AL12: 47 | AM12: 2.6111111 | AN12: 2 | AT12: 0 | BB12: NORMAL CPH | BC12: SAHARA | BE12: CAPTURED
A13: IHS_CBT_102M | B13: Richmond | C13: GNM | D13: FACKSON | E13: Copperbelt | F13: Mwenya Banda | G13: Chrispin Lindundu | I13: Indoor | J13: Grid-Gen | M13: Green Field | O13: 46030 | P13: 46006 | S13: Gen Logic | U13: 16 | W13: 3843 | X13: 3986 | Y13: 143 | Z13: 576 | AA13: OK | AF13: 656 | AI13: 52 | AJ13: 200 | AK13: 252 | AL13: 604 | AM13: 4.2237762 | AN13: 2 | AT13: 0 | BB13: NORMAL CPH | BC13: SAHARA | BE13: CAPTURED
A14: IHS_CBT_330A | B14: =IF(A14="","",VLOOKUP(A14,'IHS DATABASE'!C:D,2,0)) -> Funda Junction (Mumena_5) | C14: GNM | D14: KAMBOLE | E14: =IF(A14="","",VLOOKUP(A14,'IHS DATABASE'!C:G,5,0)) -> Copperbelt | F14: =IF(A14="","",VLOOKUP(A14,'IHS DATABASE'!C:AB,26,0)) -> Mwenya Banda | G14: =IF(A14="","",VLOOKUP(A14,'IHS DATABASE'!C:X,22,0)) -> Chrispin Lindundu | I14: =IF(A14="","",VLOOKUP(A14,'IHS DATABASE'!C:W,21,0)) -> Outdoor | J14: =IF(A14="","",VLOOKUP(A14,'IHS DATABASE'!C:T,18,0)) -> Grid-Gen | M14: =IF(A14="","",VLOOKUP(A14,'IHS DATABASE'!C:U,19,0)) -> Green Field | O14: 46030 | P14: 46030 | S14: =IF(A14="","",VLOOKUP(A14,'IHS DATABASE'!C:BG,30,0)) -> METCO | U14: =IF(A14="","",VLOOKUP(A14,'IHS DATABASE'!C:AG,31,0)) -> 15 | W14: faulty Controller | X14: Faulty Controller | Y14: =X14-W14 -> #VALUE! | Z14: =(O14-P14)*24 -> 0 | AA14: =IF(Y14>Z14,"inconsitent RH","OK") -> #VALUE! | AF14: =AJ14+AI14 -> 55 | AI14: 5 | AJ14: 50 | AK14: =AJ14+AI14 -> 55 | AL14: =AF14-AI14 -> 50 | AM14: =AL14/Y14 -> #VALUE! | AN14: =IF(A14="","",VLOOKUP(A14,'IHS DATABASE'!C:H,6,0)) -> 1.8 | AT14: =AR14-AS14 -> 0 | BB14: FAULTY CONTROLLER | BC14: SAHARA | BE14: CAPTURED
A15: IHS_CBT_113M | B15: Green Belt | C15: GNM | D15: JAULA | E15: Copperbelt | F15: Mwenya Banda | G15: Chrispin Lindundu | I15: Indoor | J15: Grid-Gen | M15: Green Field | O15: 46030 | P15: 46010 | S15: IMG | U15: 20 | W15: 11835 | X15: 11922 | Y15: 87 | Z15: 480 | AA15: OK | AF15: 771 | AI15: 255 | AJ15: 200 | AK15: 455 | AL15: 516 | AM15: 5.9310345 | AN15: 2.5 | AT15: 0 | BB15: NORMAL CPH | BC15: SAHARA | BE15: CAPTURED
A16: IHS_CBT_119M | B16: Lumumba | C16: GNM | D16: SAMUEL | E16: Copperbelt | F16: Mwenya Banda | G16: Chrispin Lindundu | I16: Indoor | J16: Grid-Gen | M16: Green Field | O16: 46030 | P16: 46361 | S16: Gen Logic | U16: 16 | W16: faulty Controller | X16: Faulty Controller | Y16: #VALUE! | Z16: -7944 | AA16: #VALUE! | AF16: 82 | AI16: 0 | AJ16: 200 | AK16: 200 | AL16: 82 | AM16: #VALUE! | AN16: 2 | AT16: 0 | BB16: FAULTY CONTROLLER | BC16: SAHARA | BE16: CAPTURED
A17: IHS_CBT_159M | B17: =IF(A17="","",VLOOKUP(A17,'IHS DATABASE'!C:D,2,0)) -> Chembe South | C17: GNM | D17: SAMUEL | E17: =IF(A17="","",VLOOKUP(A17,'IHS DATABASE'!C:G,5,0)) -> Copperbelt | F17: =IF(A17="","",VLOOKUP(A17,'IHS DATABASE'!C:AB,26,0)) -> Mwenya Banda | G17: =IF(A17="","",VLOOKUP(A17,'IHS DATABASE'!C:X,22,0)) -> Chrispin Lindundu | I17: =IF(A17="","",VLOOKUP(A17,'IHS DATABASE'!C:W,21,0)) -> Indoor | J17: =IF(A17="","",VLOOKUP(A17,'IHS DATABASE'!C:T,18,0)) -> Grid-Gen | M17: =IF(A17="","",VLOOKUP(A17,'IHS DATABASE'!C:U,19,0)) -> Green Field | O17: 46030 | P17: 46030 | S17: =IF(A17="","",VLOOKUP(A17,'IHS DATABASE'!C:BG,30,0)) -> Gen Logic | U17: =IF(A17="","",VLOOKUP(A17,'IHS DATABASE'!C:AG,31,0)) -> 20 | W17: faulty Controller | X17: Faulty Controller | Y17: =X17-W17 -> #VALUE! | Z17: =(O17-P17)*24 -> 0 | AA17: =IF(Y17>Z17,"inconsitent RH","OK") -> #VALUE! | AF17: =AJ17+AI17 -> 210 | AI17: 10 | AJ17: 200 | AK17: =AJ17+AI17 -> 210 | AL17: =AF17-AI17 -> 200 | AM17: =AL17/Y17 -> #VALUE! | AN17: =IF(A17="","",VLOOKUP(A17,'IHS DATABASE'!C:H,6,0)) -> 2.5 | AT17: =AR17-AS17 -> 0 | BB17: FAULTY CONTROLLER | BC17: SAHARA | BE17: CAPTURED
A18: IHS_CBT_233A | B18: CHIPULUKUSU | C18: GNM | D18: KAMBOLE | E18: Copperbelt | F18: Mwenya Banda | G18: Elvis Mumba | I18: Indoor | J18: Grid-Gen | M18: Green Field | O18: 46030 | P18: 46029 | S18: Earth Technology | U18: 15 | W18: 6447 | X18: 6462 | Y18: 15 | Z18: 24 | AA18: OK | AF18: 222 | AI18: 147 | AJ18: 200 | AK18: 347 | AL18: 75 | AM18: 5 | AN18: 1.8 | AT18: 0 | BB18: NORMAL CPH | BC18: SAHARA | BE18: CAPTURED
A19: IHS_CBT_267A | B19: KALULUSHI EAST | C19: GNM | D19: SAMUEL | E19: Copperbelt | F19: Mwenya Banda | G19: Chrispin Lindundu | I19: Indoor | J19: Grid-Gen | M19: Green Field | O19: 46030 | P19: 46021 | S19: Gen Logic | U19: 16 | W19: 15030 | X19: 15084 | Y19: 54 | Z19: 216 | AA19: OK | AF19: 247 | AI19: 20 | AJ19: 200 | AK19: 220 | AL19: 227 | AM19: 4.2037037 | AN19: 2 | AT19: 0 | BB19: NORMAL CPH | BC19: SAHARA | BE19: CAPTURED
A20: IHS_CBT_237A | B20: NKANA WEST | C20: GNM | D20: FACKSON | E20: Copperbelt | F20: Mwenya Banda | G20: Chrispin Lindundu | I20: Indoor | J20: Grid-Gen | M20: Green Field | O20: 46030 | P20: 46029 | S20: Earth technology | U20: 20 | W20: 13766 | X20: 13785 | Y20: 19 | Z20: 24 | AA20: OK | AF20: 220 | AI20: 145 | AJ20: 150 | AK20: 295 | AL20: 75 | AM20: 3.9473684 | AN20: 2.5 | AT20: 0 | BB20: NORMAL CPH | BC20: SAHARA | BE20: CAPTURED
A21: IHS_CBT_241A | B21: BULANGILILO | C21: GNM | D21: JAULA | E21: Copperbelt | F21: Mwenya Banda | G21: Chrispin Lindundu | I21: Outdoor | J21: Grid-Gen | M21: Green Field | O21: 46030 | P21: 46029 | S21: perkins | U21: 20 | W21: 4651 | X21: 4677 | Y21: 26 | Z21: 24 | AA21: inconsitent RH | AF21: 177 | AI21: 64 | AJ21: 150 | AK21: 214 | AL21: 113 | AM21: 4.3461538 | AN21: 2.5 | AT21: 0 | BB21: NORMAL CPH | BC21: SAHARA | BE21: CAPTURED
A22: IHS_CBT_301A | B22: CHIBULUMA TOWN | C22: GNM | D22: SAMUEL | E22: Copperbelt | F22: Mwenya Banda | G22: Chrispin Lindundu | I22: Indoor | J22: Grid-Gen | M22: Green Field | O22: 46030 | P22: 46361 | S22: Gen Logic | U22: 16 | W22: 11306 | X22: 11332 | Y22: 26 | Z22: -7944 | AA22: inconsitent RH | AF22: 106 | AI22: 5 | AJ22: 200 | AK22: 205 | AL22: 101 | AM22: 3.8846154 | AN22: 2 | AT22: 0 | BB22: NORMAL CPH | BC22: SAHARA | BE22: CAPTURED
A23: IHS_CBT_361A | B23: Mitengo TDRC | C23: GNM | D23: KAMBOLE | E23: Copperbelt | F23: Mwenya Banda | G23: Elvis Mumba | I23: Outdoor | J23: Grid-Gen | M23: Green Field | O23: 46030 | P23: 46029 | S23: CK Works | U23: 20 | W23: faulty Controller | X23: Faulty Controller | Y23: #VALUE! | Z23: 24 | AA23: #VALUE! | AF23: 157 | AI23: 96 | AJ23: 150 | AK23: 246 | AL23: 61 | AM23: #VALUE! | AN23: 2.5 | AT23: 0 | BB23: FAULTY CONTROLLER | BC23: SAHARA | BE23: CAPTURED
A24: IHS_CBT_373A | B24: ESTHER LUNGU SEC SCH | C24: GNM | D24: FACKSON | E24: #N/A | F24: #N/A | G24: #N/A | I24: #N/A | J24: #N/A | M24: #N/A | O24: 46030 | P24: 46025 | S24: #N/A | U24: #N/A | W24: 329 | X24: 406 | Y24: 77 | Z24: 120 | AA24: OK | AF24: 328 | AI24: 130 | AJ24: 150 | AK24: 280 | AL24: 198 | AM24: 2.5714286 | AN24: #N/A | AT24: 0 | BB24: NORMAL CPH | BC24: SAHARA | BE24: CAPTURED
A25: IHS_CBT_369A | B25: Buntungwa | C25: GNM | D25: ISAAC | E25: #N/A | F25: #N/A | G25: #N/A | I25: #N/A | J25: #N/A | M25: #N/A | O25: 46030 | P25: 46029 | S25: #N/A | U25: #N/A | W25: 755 | X25: 766 | Y25: =X25-W25 -> 11 | Z25: 24 | AA25: OK | AF25: 173 | AI25: 129 | AJ25: 200 | AK25: =AJ25+AI25 -> 329 | AL25: =AF25-AI25 -> 44 | AM25: =AL25/Y25 -> 4 | AN25: #N/A | AT25: 0 | BB25: NORMAL CPH | BC25: PUMA | BE25: CAPTURED
A26: IHS_CBT_370A | B26: KITWE WEST KAMAKONDE | C26: GNM | D26: SAMUEL | E26: #N/A | F26: #N/A | G26: #N/A | I26: #N/A | J26: #N/A | M26: #N/A | O26: 46030 | P26: 46024 | S26: #N/A | U26: #N/A | W26: 254 | X26: 373 | Y26: 119 | Z26: 144 | AA26: OK | AF26: 300 | AI26: 5 | AJ26: 200 | AK26: 205 | AL26: 295 | AM26: 2.4789916 | AN26: #N/A | AT26: 0 | BB26: NORMAL CPH | BC26: SAHARA | BE26: CAPTURED
A27: IHS_CBT_378A | B27: NDOLA HILLSIDE | C27: GNM | D27: ROYD | E27: #N/A | F27: #N/A | G27: #N/A | I27: #N/A | J27: #N/A | M27: #N/A | O27: 46030 | P27: 46022 | S27: #N/A | U27: #N/A | W27: 0 | X27: 73 | Y27: 73 | Z27: 192 | AA27: OK | AF27: 200 | AI27: 0 | AJ27: 200 | AK27: 200 | AL27: 200 | AM27: 2.739726 | AN27: #N/A | AT27: 0 | BB27: NORMAL CPH | BC27: SAHARA | BE27: CAPTURED
C28: =IF(A28="","",VLOOKUP(A28,'[3]IHS DATABASE'!C:AD,27,0)) | E28: =IF(A28="","",VLOOKUP(A28,'[3]IHS DATABASE'!C:G,5,0)) | F28: =IF(A28="","",VLOOKUP(A28,'[3]IHS DATABASE'!C:AB,26,0)) | G28: =IF(A28="","",VLOOKUP(A28,'[3]IHS DATABASE'!C:X,22,0)) | I28: =IF(A28="","",VLOOKUP(A28,'[3]IHS DATABASE'!C:W,21,0)) | J28: =IF(A28="","",VLOOKUP(A28,'[3]IHS DATABASE'!C:T,18,0)) | M28: =IF(A28="","",VLOOKUP(A28,'[3]IHS DATABASE'!C:U,19,0)) | S28: =IF(A28="","",VLOOKUP(A28,'[3]IHS DATABASE'!C:BG,30,0)) | U28: =IF(A28="","",VLOOKUP(A28,'[3]IHS DATABASE'!C:AG,31,0)) | Y28: =X28-W28 -> 0 | Z28: =(O28-P28)*24 -> 0 | AA28: =IF(Y28>Z28,"inconsitent RH","OK") -> OK | AK28: =AJ28+AI28 -> 0 | AL28: =AF28-AI28 -> 0 | AM28: =AL28/Y28 -> #DIV/0! | AN28: =IF(A28="","",VLOOKUP(A28,'[3]IHS DATABASE'!C:H,6,0)) | AT28: =AR28-AS28 -> 0
C29: =IF(A29="","",VLOOKUP(A29,'[3]IHS DATABASE'!C:AD,27,0)) | E29: =IF(A29="","",VLOOKUP(A29,'[3]IHS DATABASE'!C:G,5,0)) | F29: =IF(A29="","",VLOOKUP(A29,'[3]IHS DATABASE'!C:AB,26,0)) | G29: =IF(A29="","",VLOOKUP(A29,'[3]IHS DATABASE'!C:X,22,0)) | I29: =IF(A29="","",VLOOKUP(A29,'[3]IHS DATABASE'!C:W,21,0)) | J29: =IF(A29="","",VLOOKUP(A29,'[3]IHS DATABASE'!C:T,18,0)) | M29: =IF(A29="","",VLOOKUP(A29,'[3]IHS DATABASE'!C:U,19,0)) | S29: =IF(A29="","",VLOOKUP(A29,'[3]IHS DATABASE'!C:BG,30,0)) | U29: =IF(A29="","",VLOOKUP(A29,'[3]IHS DATABASE'!C:AG,31,0)) | Y29: =X29-W29 -> 0 | Z29: =(O29-P29)*24 -> 0 | AA29: =IF(Y29>Z29,"inconsitent RH","OK") -> OK | AK29: =AJ29+AI29 -> 0 | AL29: =AF29-AI29 -> 0 | AM29: =AL29/Y29 -> #DIV/0! | AN29: =IF(A29="","",VLOOKUP(A29,'[3]IHS DATABASE'!C:H,6,0)) | AT29: =AR29-AS29 -> 0
C30: =IF(A30="","",VLOOKUP(A30,'[3]IHS DATABASE'!C:AD,27,0)) | E30: =IF(A30="","",VLOOKUP(A30,'[3]IHS DATABASE'!C:G,5,0)) | F30: =IF(A30="","",VLOOKUP(A30,'[3]IHS DATABASE'!C:AB,26,0)) | G30: =IF(A30="","",VLOOKUP(A30,'[3]IHS DATABASE'!C:X,22,0)) | I30: =IF(A30="","",VLOOKUP(A30,'[3]IHS DATABASE'!C:W,21,0)) | J30: =IF(A30="","",VLOOKUP(A30,'[3]IHS DATABASE'!C:T,18,0)) | M30: =IF(A30="","",VLOOKUP(A30,'[3]IHS DATABASE'!C:U,19,0)) | S30: =IF(A30="","",VLOOKUP(A30,'[3]IHS DATABASE'!C:BG,30,0)) | U30: =IF(A30="","",VLOOKUP(A30,'[3]IHS DATABASE'!C:AG,31,0)) | Y30: =X30-W30 -> 0 | Z30: =(O30-P30)*24 -> 0 | AA30: =IF(Y30>Z30,"inconsitent RH","OK") -> OK | AK30: =AJ30+AI30 -> 0 | AL30: =AF30-AI30 -> 0 | AM30: =AL30/Y30 -> #DIV/0! | AN30: =IF(A30="","",VLOOKUP(A30,'[3]IHS DATABASE'!C:H,6,0)) | AT30: =AR30-AS30 -> 0
C31: =IF(A31="","",VLOOKUP(A31,'[3]IHS DATABASE'!C:AD,27,0)) | E31: =IF(A31="","",VLOOKUP(A31,'[3]IHS DATABASE'!C:G,5,0)) | F31: =IF(A31="","",VLOOKUP(A31,'[3]IHS DATABASE'!C:AB,26,0)) | G31: =IF(A31="","",VLOOKUP(A31,'[3]IHS DATABASE'!C:X,22,0)) | I31: =IF(A31="","",VLOOKUP(A31,'[3]IHS DATABASE'!C:W,21,0)) | J31: =IF(A31="","",VLOOKUP(A31,'[3]IHS DATABASE'!C:T,18,0)) | M31: =IF(A31="","",VLOOKUP(A31,'[3]IHS DATABASE'!C:U,19,0)) | S31: =IF(A31="","",VLOOKUP(A31,'[3]IHS DATABASE'!C:BG,30,0)) | U31: =IF(A31="","",VLOOKUP(A31,'[3]IHS DATABASE'!C:AG,31,0)) | Y31: =X31-W31 -> 0 | Z31: =(O31-P31)*24 -> 0 | AA31: =IF(Y31>Z31,"inconsitent RH","OK") -> OK | AK31: =AJ31+AI31 -> 0 | AL31: =AF31-AI31 -> 0 | AM31: =AL31/Y31 -> #DIV/0! | AN31: =IF(A31="","",VLOOKUP(A31,'[3]IHS DATABASE'!C:H,6,0)) | AT31: =AR31-AS31 -> 0
C32: =IF(A32="","",VLOOKUP(A32,'[3]IHS DATABASE'!C:AD,27,0)) | E32: =IF(A32="","",VLOOKUP(A32,'[3]IHS DATABASE'!C:G,5,0)) | F32: =IF(A32="","",VLOOKUP(A32,'[3]IHS DATABASE'!C:AB,26,0)) | G32: =IF(A32="","",VLOOKUP(A32,'[3]IHS DATABASE'!C:X,22,0)) | I32: =IF(A32="","",VLOOKUP(A32,'[3]IHS DATABASE'!C:W,21,0)) | J32: =IF(A32="","",VLOOKUP(A32,'[3]IHS DATABASE'!C:T,18,0)) | M32: =IF(A32="","",VLOOKUP(A32,'[3]IHS DATABASE'!C:U,19,0)) | S32: =IF(A32="","",VLOOKUP(A32,'[3]IHS DATABASE'!C:BG,30,0)) | U32: =IF(A32="","",VLOOKUP(A32,'[3]IHS DATABASE'!C:AG,31,0)) | Y32: =X32-W32 -> 0 | Z32: =(O32-P32)*24 -> 0 | AA32: =IF(Y32>Z32,"inconsitent RH","OK") -> OK | AK32: =AJ32+AI32 -> 0 | AL32: =AF32-AI32 -> 0 | AM32: =AL32/Y32 -> #DIV/0! | AN32: =IF(A32="","",VLOOKUP(A32,'[3]IHS DATABASE'!C:H,6,0)) | AT32: =AR32-AS32 -> 0
C33: =IF(A33="","",VLOOKUP(A33,'[3]IHS DATABASE'!C:AD,27,0)) | E33: =IF(A33="","",VLOOKUP(A33,'[3]IHS DATABASE'!C:G,5,0)) | F33: =IF(A33="","",VLOOKUP(A33,'[3]IHS DATABASE'!C:AB,26,0)) | G33: =IF(A33="","",VLOOKUP(A33,'[3]IHS DATABASE'!C:X,22,0)) | I33: =IF(A33="","",VLOOKUP(A33,'[3]IHS DATABASE'!C:W,21,0)) | J33: =IF(A33="","",VLOOKUP(A33,'[3]IHS DATABASE'!C:T,18,0)) | M33: =IF(A33="","",VLOOKUP(A33,'[3]IHS DATABASE'!C:U,19,0)) | S33: =IF(A33="","",VLOOKUP(A33,'[3]IHS DATABASE'!C:BG,30,0)) | U33: =IF(A33="","",VLOOKUP(A33,'[3]IHS DATABASE'!C:AG,31,0)) | Y33: =X33-W33 -> 0 | Z33: =(O33-P33)*24 -> 0 | AA33: =IF(Y33>Z33,"inconsitent RH","OK") -> OK | AK33: =AJ33+AI33 -> 0 | AL33: =AF33-AI33 -> 0 | AM33: =AL33/Y33 -> #DIV/0! | AN33: =IF(A33="","",VLOOKUP(A33,'[3]IHS DATABASE'!C:H,6,0)) | AT33: =AR33-AS33 -> 0
C34: =IF(A34="","",VLOOKUP(A34,'[3]IHS DATABASE'!C:AD,27,0)) | E34: =IF(A34="","",VLOOKUP(A34,'[3]IHS DATABASE'!C:G,5,0)) | F34: =IF(A34="","",VLOOKUP(A34,'[3]IHS DATABASE'!C:AB,26,0)) | G34: =IF(A34="","",VLOOKUP(A34,'[3]IHS DATABASE'!C:X,22,0)) | I34: =IF(A34="","",VLOOKUP(A34,'[3]IHS DATABASE'!C:W,21,0)) | J34: =IF(A34="","",VLOOKUP(A34,'[3]IHS DATABASE'!C:T,18,0)) | M34: =IF(A34="","",VLOOKUP(A34,'[3]IHS DATABASE'!C:U,19,0)) | S34: =IF(A34="","",VLOOKUP(A34,'[3]IHS DATABASE'!C:BG,30,0)) | U34: =IF(A34="","",VLOOKUP(A34,'[3]IHS DATABASE'!C:AG,31,0)) | Y34: =X34-W34 -> 0 | Z34: =(O34-P34)*24 -> 0 | AA34: =IF(Y34>Z34,"inconsitent RH","OK") -> OK | AK34: =AJ34+AI34 -> 0 | AL34: =AF34-AI34 -> 0 | AM34: =AL34/Y34 -> #DIV/0! | AN34: =IF(A34="","",VLOOKUP(A34,'[3]IHS DATABASE'!C:H,6,0)) | AT34: =AR34-AS34 -> 0
C35: =IF(A35="","",VLOOKUP(A35,'[3]IHS DATABASE'!C:AD,27,0)) | E35: =IF(A35="","",VLOOKUP(A35,'[3]IHS DATABASE'!C:G,5,0)) | F35: =IF(A35="","",VLOOKUP(A35,'[3]IHS DATABASE'!C:AB,26,0)) | G35: =IF(A35="","",VLOOKUP(A35,'[3]IHS DATABASE'!C:X,22,0)) | I35: =IF(A35="","",VLOOKUP(A35,'[3]IHS DATABASE'!C:W,21,0)) | J35: =IF(A35="","",VLOOKUP(A35,'[3]IHS DATABASE'!C:T,18,0)) | M35: =IF(A35="","",VLOOKUP(A35,'[3]IHS DATABASE'!C:U,19,0)) | S35: =IF(A35="","",VLOOKUP(A35,'[3]IHS DATABASE'!C:BG,30,0)) | U35: =IF(A35="","",VLOOKUP(A35,'[3]IHS DATABASE'!C:AG,31,0)) | Y35: =X35-W35 -> 0 | Z35: =(O35-P35)*24 -> 0 | AA35: =IF(Y35>Z35,"inconsitent RH","OK") -> OK | AK35: =AJ35+AI35 -> 0 | AL35: =AF35-AI35 -> 0 | AM35: =AL35/Y35 -> #DIV/0! | AN35: =IF(A35="","",VLOOKUP(A35,'[3]IHS DATABASE'!C:H,6,0)) | AT35: =AR35-AS35 -> 0
C36: =IF(A36="","",VLOOKUP(A36,'[3]IHS DATABASE'!C:AD,27,0)) | E36: =IF(A36="","",VLOOKUP(A36,'[3]IHS DATABASE'!C:G,5,0)) | F36: =IF(A36="","",VLOOKUP(A36,'[3]IHS DATABASE'!C:AB,26,0)) | G36: =IF(A36="","",VLOOKUP(A36,'[3]IHS DATABASE'!C:X,22,0)) | I36: =IF(A36="","",VLOOKUP(A36,'[3]IHS DATABASE'!C:W,21,0)) | J36: =IF(A36="","",VLOOKUP(A36,'[3]IHS DATABASE'!C:T,18,0)) | M36: =IF(A36="","",VLOOKUP(A36,'[3]IHS DATABASE'!C:U,19,0)) | S36: =IF(A36="","",VLOOKUP(A36,'[3]IHS DATABASE'!C:BG,30,0)) | U36: =IF(A36="","",VLOOKUP(A36,'[3]IHS DATABASE'!C:AG,31,0)) | Y36: =X36-W36 -> 0 | Z36: =(O36-P36)*24 -> 0 | AA36: =IF(Y36>Z36,"inconsitent RH","OK") -> OK | AK36: =AJ36+AI36 -> 0 | AL36: =AF36-AI36 -> 0 | AM36: =AL36/Y36 -> #DIV/0! | AN36: =IF(A36="","",VLOOKUP(A36,'[3]IHS DATABASE'!C:H,6,0)) | AT36: =AR36-AS36 -> 0
C37: =IF(A37="","",VLOOKUP(A37,'[3]IHS DATABASE'!C:AD,27,0)) | E37: =IF(A37="","",VLOOKUP(A37,'[3]IHS DATABASE'!C:G,5,0)) | F37: =IF(A37="","",VLOOKUP(A37,'[3]IHS DATABASE'!C:AB,26,0)) | G37: =IF(A37="","",VLOOKUP(A37,'[3]IHS DATABASE'!C:X,22,0)) | I37: =IF(A37="","",VLOOKUP(A37,'[3]IHS DATABASE'!C:W,21,0)) | J37: =IF(A37="","",VLOOKUP(A37,'[3]IHS DATABASE'!C:T,18,0)) | M37: =IF(A37="","",VLOOKUP(A37,'[3]IHS DATABASE'!C:U,19,0)) | S37: =IF(A37="","",VLOOKUP(A37,'[3]IHS DATABASE'!C:BG,30,0)) | U37: =IF(A37="","",VLOOKUP(A37,'[3]IHS DATABASE'!C:AG,31,0)) | Y37: =X37-W37 -> 0 | Z37: =(O37-P37)*24 -> 0 | AA37: =IF(Y37>Z37,"inconsitent RH","OK") -> OK | AK37: =AJ37+AI37 -> 0 | AL37: =AF37-AI37 -> 0 | AM37: =AL37/Y37 -> #DIV/0! | AN37: =IF(A37="","",VLOOKUP(A37,'[3]IHS DATABASE'!C:H,6,0)) | AT37: =AR37-AS37 -> 0
C38: =IF(A38="","",VLOOKUP(A38,'[3]IHS DATABASE'!C:AD,27,0)) | E38: =IF(A38="","",VLOOKUP(A38,'[3]IHS DATABASE'!C:G,5,0)) | F38: =IF(A38="","",VLOOKUP(A38,'[3]IHS DATABASE'!C:AB,26,0)) | G38: =IF(A38="","",VLOOKUP(A38,'[3]IHS DATABASE'!C:X,22,0)) | I38: =IF(A38="","",VLOOKUP(A38,'[3]IHS DATABASE'!C:W,21,0)) | J38: =IF(A38="","",VLOOKUP(A38,'[3]IHS DATABASE'!C:T,18,0)) | M38: =IF(A38="","",VLOOKUP(A38,'[3]IHS DATABASE'!C:U,19,0)) | S38: =IF(A38="","",VLOOKUP(A38,'[3]IHS DATABASE'!C:BG,30,0)) | U38: =IF(A38="","",VLOOKUP(A38,'[3]IHS DATABASE'!C:AG,31,0)) | Y38: =X38-W38 -> 0 | Z38: =(O38-P38)*24 -> 0 | AA38: =IF(Y38>Z38,"inconsitent RH","OK") -> OK | AK38: =AJ38+AI38 -> 0 | AL38: =AF38-AI38 -> 0 | AM38: =AL38/Y38 -> #DIV/0! | AN38: =IF(A38="","",VLOOKUP(A38,'[3]IHS DATABASE'!C:H,6,0)) | AT38: =AR38-AS38 -> 0
C39: =IF(A39="","",VLOOKUP(A39,'[3]IHS DATABASE'!C:AD,27,0)) | E39: =IF(A39="","",VLOOKUP(A39,'[3]IHS DATABASE'!C:G,5,0)) | F39: =IF(A39="","",VLOOKUP(A39,'[3]IHS DATABASE'!C:AB,26,0)) | G39: =IF(A39="","",VLOOKUP(A39,'[3]IHS DATABASE'!C:X,22,0)) | I39: =IF(A39="","",VLOOKUP(A39,'[3]IHS DATABASE'!C:W,21,0)) | J39: =IF(A39="","",VLOOKUP(A39,'[3]IHS DATABASE'!C:T,18,0)) | M39: =IF(A39="","",VLOOKUP(A39,'[3]IHS DATABASE'!C:U,19,0)) | S39: =IF(A39="","",VLOOKUP(A39,'[3]IHS DATABASE'!C:BG,30,0)) | U39: =IF(A39="","",VLOOKUP(A39,'[3]IHS DATABASE'!C:AG,31,0)) | Y39: =X39-W39 -> 0 | Z39: =(O39-P39)*24 -> 0 | AA39: =IF(Y39>Z39,"inconsitent RH","OK") -> OK | AK39: =AJ39+AI39 -> 0 | AL39: =AF39-AI39 -> 0 | AM39: =AL39/Y39 -> #DIV/0! | AN39: =IF(A39="","",VLOOKUP(A39,'[3]IHS DATABASE'!C:H,6,0)) | AT39: =AR39-AS39 -> 0
... C2017: =IF(A2017="","",VLOOKUP(A2017,'[3]IHS DATABASE'!C:AD,27,0)) | E2017: =IF(A2017="","",VLOOKUP(A2017,'[3]IHS DATABASE'!C:G,5,0)) | F2017: =IF(A2017="","",VLOOKUP(A2017,'[3]IHS DATABASE'!C:AB,26,0)) | G2017: =IF(A2017="","",VLOOKUP(A2017,'[3]IHS DATABASE'!C:X,22,0)) | I2017: =IF(A2017="","",VLOOKUP(A2017,'[3]IHS DATABASE'!C:W,21,0)) | J2017: =IF(A2017="","",VLOOKUP(A2017,'[3]IHS DATABASE'!C:T,18,0)) | M2017: =IF(A2017="","",VLOOKUP(A2017,'[3]IHS DATABASE'!C:U,19,0)) | S2017: =IF(A2017="","",VLOOKUP(A2017,'[3]IHS DATABASE'!C:BG,30,0)) | U2017: =IF(A2017="","",VLOOKUP(A2017,'[3]IHS DATABASE'!C:AG,31,0)) | Y2017: =X2017-W2017 -> 0 | Z2017: =(O2017-P2017)*24 -> 0 | AA2017: =IF(Y2017>Z2017,"inconsitent RH","OK") -> OK | AK2017: =AJ2017+AI2017 -> 0 | AL2017: =AF2017-AI2017 -> 0 | AM2017: =AL2017/Y2017 -> #DIV/0! | AN2017: =IF(A2017="","",VLOOKUP(A2017,'[3]IHS DATABASE'!C:H,6,0)) | AT2017: =AR2017-AS2017 -> 0
...

Sheet IHS DATABASE
A1: # | B1: Client ID | C1: Site ID | D1: Site Name | E1: Longitude | F1: Latitude | G1: Region | H1: Manufacturers CPH | I1: State | J1: District | K1: Liquid Fiber (Y/N) | L1: MTN Fiber (Y/N) | M1: Airtel Fiber (Y/N) | N1: Demo. Classification | O1: Technology | P1: Site Classification 2. (Platinum/Gold/Silver) | Q1: TIS Priority | R1: TIS | S1: Tower Status | T1: Power Topology | U1: Tower Type | V1: Tower Height (m) | W1: Site Configuration (Indoor/Outdoor) | X1: zu | Y1: Maintenance Technician Inhouse | Z1: Refueling Technician Inhouse | AA1: MNO | AB1: RM | AC1: Subcon | AD1: Refuelling Subcon | AE1: Assembler | AF1: Gen Make | AG1: Gen Capacity (KVA) | AH1: Engine Brand | AI1: Engine Model | AJ1: Alternator Brand | AK1: Alternator Model | AL1: Tank Size (L) | AM1: Rectifier Brand | AN1: Rectifier Model | AO1: Rectifier Capacity (A) | AP1: Battery Brand | AQ1: Site Battery Capcity | AR1: One Battery Voltage (V) | AS1: One Battery Amperage (AH) | AT1: Number of batteries | AU1: Aircon 1 Brand | AV1: Aircon 2 Brand | AW1: Capacity (BTU) ac1 | AX1: Capacity (BTU)ac2 | AY1: Number of Aircons | AZ1: Total DC loads (A) | BA1: Total DC load (KW) | BB1: No. of tenants on site | BC1: Tenants on site | BD1: MTN Site ID | BE1: AIRTEL Site ID | BF1: Fire Extinguisher (yes/No) | BG1: Fire Extinguisher service date | BH1: Security light(working/not working) | BI1: palisade/mesh | BJ1: Inala/Netco | BK1: Date Updated | BL1: BUB requirements | BM1: BUB allocated | BN1: Idle BUB | BO1: BUB collected | BP1: region offices | BQ1: Remarks | BR1: status | BS1: BUB installation Date | BT1: Mains Rectifier | BU1: hauwei solar | BV1: DG Swaps | BW1: Idle DGs | BX1: DGs collected | BY1: Allocation | BZ1: Reccommended DG capacity ( KVA ) | CA1: date installed | CB1: Status | CC1: Average Solar/Hybrid Running Hours (hrs per day, for last quarter period) | CD1: Average Grid (hrs per day, for last quarter period) | CE1: Average Generator Running Hours (hrs per day, for last quarter period) | CF1: Remarks | CG1: Comment
A2: 1 | C2: IHS_LSK_477A | D2: New Kenneth Kaunda International Airport | E2: 28.4493 | F2: -15.3257 | G2: Lusaka | H2: #N/A | I2: Lusaka | J2: Lusaka | K2: No | L2: No | M2: No | N2: Rural | O2: Silver | P2: Silver | Q2: BTS | R2: BTS | S2: On Air | T2: Grid only | U2: Green Field | V2: RT | W2: Outdoor | X2: Kennedy Mwansa | Y2: N/A | Z2: N/A | AA2: Airtel | AB2: Evans Ngonga | AC2: In House | AD2: In House | AE2: perkins | AL2: N/A | AM2: Power cube | AP2: Lithium | AQ2: 100 | AR2: 48 | AS2: 100 | AT2: 2 | AU2: N/A | AV2: N/A | AW2: N/A | AX2: N/A | AY2: N/A | AZ2: 32 | CG2: IHS_LSK_477A
A3: 624 | B3: T3299 | C3: IHS_CBT_001M | D3: Kanini | E3: 28.6277 | F3: -12.97624 | G3: Copperbelt | H3: 2.5 | I3: COPPERBELT | J3: NDOLA | K3: Yes | L3: Yes | M3: No | N3: Urban | O3: 2G 3G 4G | P3: P3 | Q3: BTS | R3: BTS | S3: On Air | T3: Grid-Gen | U3: Green Field | V3: 60 | W3: Outdoor | X3: Elvis Mumba | Y3: SBC | Z3: SBC | AA3: MTN | AB3: Mwenya Banda | AC3: GNM | AD3: GNM | AE3: IMG | AF3: IMG | AG3: 20 | AH3: perkins | AI3: 0 | AJ3: Leroy Sommer | AK3: 0 | AL3: 600 | AM3: Power cube | AN3: ICC330-H1-C1 | AO3: 400 | AP3: Lithium | AQ3: 400 | AR3: 48 | AS3: 100 | AT3: =AQ3/AS3 -> 4 | AU3: N/A | AV3: N/A | AW3: N/A | AX3: n/a | AY3: N/A | AZ3: 116.4 | BA3: 0 | BB3: 3 | BC3: MTNAirtelLiquid Telecom | BD3: T3299 | BE3: ZM6957 | BF3: yes | BH3: 0 | BI3: Palisade | BJ3: Inala | BK3: 44778 | BL3: No | BM3: No | BT3: No | BU3: No | BV3: No | BY3: n/a | BZ3: n/a | CB3: n/a | CG3: IHS_CBT_001M
A4: 408 | B4: T3202 | D4: Hillcrest | E4: 28.61934 | F4: -12.98005 | G4: Copperbelt | H4: 2.5 | I4: COPPERBELT | J4: NDOLA | K4: Yes | L4: Yes | M4: No | N4: Urban | O4: 2G 3G | P4: P4 | Q4: BTS | R4: BTS | S4: On Air | T4: Grid-Gen | U4: Green Field | V4: 36 | W4: Indoor | X4: Elvis Mumba | Y4: SBC | Z4: SBC | AA4: MTN | AB4: Mwenya Banda | AC4: GNM | AD4: GNM | AE4: GL Yanmar | AF4: GL Yanmar | AG4: 20 | AH4: Yanmar | AI4: 4TNE | AJ4: Mecc Alte | AK4: 0 | AL4: 750 | AM4: Delta | AN4: DPS 2400B-48-5 | AO4: 250 | AP4: Wolong | AQ4: 600 | AR4: 2 | AS4: 600 | AT4: 24 | AU4: samsung | AV4: samsung | AW4: 18000 | AX4: 18000 | AY4: 2 | AZ4: 68.2 | BA4: 0 | BB4: 2 | BC4: MTNAirtel | BD4: T3202 | BE4: ZM0404 | BF4: yes | BH4: 0 | BI4: Palisade | BJ4: Inala | BK4: 44778 | BL4: No | BM4: No | BT4: No | BU4: No | BV4: No | BY4: n/a | BZ4: n/a | CB4: n/a | CG4: IHS_CBT_002M
A5: 1721 | B5: T3023 | C5: IHS_CBT_003M | D5: Swimming Pool | E5: 28.63875 | F5: -12.973283 | G5: Copperbelt | H5: 4.5 | I5: COPPERBELT | J5: NDOLA | K5: Yes | L5: Yes | M5: No | N5: Urban | O5: 2G 3G 4G | P5: P2 | Q5: BTS | R5: BB | S5: On Air | T5: Grid-Gen | U5: Green Field | V5: 60 | W5: Indoor | X5: Elvis Mumba | Y5: SBC | Z5: SBC | AA5: MTN | AB5: Mwenya Banda | AC5: GNM | AD5: GNM | AE5: CK Works | AF5: CK Works | AG5: 30 | AH5: perkins | AI5: DJ83400S | AJ5: Leroy Sommer | AK5: 0 | AL5: 1000 | AM5: Power cube | AN5: ICC330-H1-C1 | AO5: 400 | AP5: NARADA | AQ5: 1200 | AR5: 2 | AS5: 600 | AT5: 48 | AU5: LG | AV5: LG | AW5: 18000 | AX5: 18000 | AY5: 2 | AZ5: 135 | BA5: 0 | BB5: 2 | BC5: MTNAir-link | BD5: T3023 | BE5: 0 | BF5: yes | BH5: Yes | BI5: Palisade | BJ5: Inala | BK5: 44778 | BL5: No | BM5: No | BT5: No | BU5: No | BV5: No | BY5: n/a | BZ5: n/a | CB5: n/a | CG5: IHS_CBT_003M
A6: 1420 | B6: T3323 | C6: IHS_CBT_004M | D6: Ndola T. Centre | E6: 28.63965 | F6: -12.96452 | G6: Copperbelt | H6: 2.5 | I6: COPPERBELT | J6: NDOLA | K6: Yes | L6: No | M6: No | N6: Urban | O6: 2G 3G 4G | P6: P2 | Q6: BTS | R6: HUB | S6: On Air | T6: Grid-Gen | U6: Green Field | V6: 36 | W6: Outdoor | X6: Elvis Mumba | Y6: SBC | Z6: SBC | AA6: MTN | AB6: Mwenya Banda | AC6: GNM | AD6: GNM | AE6: Falcon | AF6: Falcon | AG6: 20 | AH6: perkins | AI6: GV 51790V | AJ6: Leroy Sommer | AK6: 0 | AL6: 600 | AM6: Power cube | AN6: ICC330-H1-C1 | AO6: 400 | AP6: NARADA | AQ6: 600 | AR6: 2 | AS6: 600 | AT6: 24 | AU6: N/A | AV6: N/A | AW6: N/A | AX6: n/a | AY6: N/A | AZ6: 98 | BA6: 0 | BB6: 3 | BC6: MTNAirtelLiquid Telecom | BD6: T3323 | BE6: ZM0243 | BF6: yes | BH6: 0 | BI6: Palisade | BJ6: Inala | BK6: 44778 | BL6: No | BM6: No | BT6: No | BU6: No | BV6: No | BY6: n/a | BZ6: n/a | CB6: n/a | CG6: IHS_CBT_004M
A7: 1548 | B7: T3022 | C7: IHS_CBT_005M | D7: Premium Plaza | E7: 28.6305 | F7: -12.958567 | G7: Copperbelt | H7: N/A | I7: COPPERBELT | J7: NDOLA | K7: Yes | L7: No | M7: No | N7: Urban | O7: 2G 3G 4G | P7: P2 | Q7: BTS | R7: BTS | S7: On Air | T7: Grid-Gen | U7: Roof Top | V7: RT | W7: Indoor | X7: Elvis Mumba | Y7: SBC | Z7: SBC | AA7: MTN | AB7: Mwenya Banda | AC7: CCS | AD7: In House | AE7: N/A | AF7: N/A | AG7: N/A | AH7: N/A | AI7: N/A | AJ7: N/A | AK7: N/A | AL7: N/A | AM7: Delta | AN7: DPS 2400B-48-5 | AO7: 250 | AP7: Lithium | AQ7: 300 | AR7: 48 | AS7: 100 | AT7: =AQ7/AS7 -> 3 | AU7: LG | AV7: LG | AW7: 18000 | AX7: 18000 | AY7: 2 | AZ7: 66 | BA7: 0 | BB7: 2 | BC7: MTNLiquid Telecom | BD7: T3022 | BE7: 0 | BF7: yes | BH7: 0 | BI7: Palisade | BJ7: Inala | BK7: 44778 | BL7: No | BM7: No | BT7: No | BU7: No | BV7: No | BY7: n/a | BZ7: n/a | CB7: n/a | CG7: IHS_CBT_005M
A8: 872 | B8: T3352 | C8: IHS_CBT_006M | D8: Lubuto Central | E8: 28.62047 | F8: -12.99595 | G8: Copperbelt | H8: 1.8 | I8: COPPERBELT | J8: NDOLA | K8: No | L8: Yes | M8: No | N8: Suburban | O8: 2G 3G | P8: P3 | Q8: BTS | R8: BTS | S8: On Air | T8: Grid-Gen | U8: Green Field | V8: 36 | W8: Outdoor | X8: Elvis Mumba | Y8: SBC | Z8: SBC | AA8: MTN | AB8: Mwenya Banda | AC8: GNM | AD8: GNM | AE8: Lamasat | AF8: Lamasat | AG8: 15 | AH8: perkins | AI8: 0 | AJ8: Leroy Sommer | AK8: 0 | AL8: 600 | AM8: Power cube | AN8: ICC330-HA1-C10 | AO8: 250 | AP8: Lithium | AQ8: 200 | AR8: 48 | AS8: 100 | AT8: =AQ8/AS8 -> 2 | AU8: N/A | AV8: N/A | AW8: N/A | AX8: n/a | AY8: N/A | AZ8: 88 | BA8: 0 | BB8: 1 | BC8: MTN | BD8: T3352 | BE8: 0 | BF8: yes | BH8: 0 | BI8: Palisade | BJ8: Inala | BK8: 44778 | BL8: No | BM8: No | BT8: No | BU8: No | BV8: No | BY8: n/a | BZ8: n/a | CB8: n/a | CG8: IHS_CBT_006M
A9: 1153 | B9: T3218 | C9: IHS_CBT_007M | D9: Mpelembe House | E9: 28.649749 | F9: -12.968242 | G9: Copperbelt | H9: 1.8 | I9: COPPERBELT | J9: NDOLA | K9: No | L9: Yes | M9: No | N9: Urban | O9: 2G 3G 4G | P9: P2 | Q9: BTS | R9: BTS | S9: On Air | T9: Grid-Gen | U9: Roof Top | V9: RT | W9: Outdoor | X9: Elvis Mumba | Y9: SBC | Z9: SBC | AA9: MTN | AB9: Mwenya Banda | AC9: GNM | AD9: GNM | AE9: Lamasat | AF9: Lamasat | AG9: 15 | AH9: perkins | AI9: 0 | AJ9: Leroy Sommer | AK9: 0 | AL9: 600 | AM9: Emerson | AN9: 701 IG4 | AO9: 300 | AP9: Lithium | AQ9: 300 | AR9: 48 | AS9: 100 | AT9: =AQ9/AS9 -> 3 | AU9: N/A | AV9: N/A | AW9: N/A | AX9: n/a | AY9: N/A | AZ9: 58 | BA9: 0 | BB9: 1 | BC9: MTN | BD9: T3218 | BE9: 0 | BF9: 0 | BH9: 0 | BI9: Palisade | BJ9: Inala | BK9: 44778 | BL9: No | BM9: No | BT9: No | BU9: No | BV9: No | BY9: n/a | BZ9: n/a | CB9: n/a | CG9: IHS_CBT_007M
A10: 1028 | B10: T3198 | C10: IHS_CBT_008M | D10: Masala | E10: 28.644711 | F10: -12.99421 | G10: Copperbelt | H10: 2 | I10: COPPERBELT | J10: NDOLA | K10: Yes | L10: No | M10: No | N10: Suburban | O10: 2G 3G 4G | P10: P1 | Q10: BTS | R10: BTS | S10: On Air | T10: Grid-Gen | U10: Green Field | V10: 36 | W10: Indoor | X10: Elvis Mumba | Y10: SBC | Z10: SBC | AA10: MTN | AB10: Mwenya Banda | AC10: GNM | AD10: GNM | AE10: Generator City | AF10: Generator City | AG10: 13 | AH10: Yanmar | AI10: 3TNE88-G1A | AJ10: ALPHAGEN | AK10: 0 | AL10: 600 | AM10: Delta | AN10: DPS 2400B-48-5 | AO10: 250 | AP10: NARADA | AQ10: 600 | AR10: 2 | AS10: 600 | AT10: 24 | AU10: LG | AV10: LG | AW10: 18000 | AX10: 18000 | AY10: 2 | AZ10: 110 | BA10: 0 | BB10: 1 | BC10: MTN | BD10: T3198 | BE10: 0 | BF10: yes | BH10: 0 | BI10: Palisade | BJ10: Inala | BK10: 44778 | BL10: No | BM10: No | BT10: No | BU10: No | BV10: No | BY10: n/a | BZ10: n/a | CB10: n/a | CG10: IHS_CBT_008M
A11: 1730 | B11: T3024 | C11: IHS_CBT_009M | D11: Tazama Building | E11: 28.652017 | F11: -12.969333 | G11: Copperbelt | H11: 2 | I11: COPPERBELT | J11: NDOLA | K11: No | L11: No | M11: No | N11: Urban | O11: 2G 3G 4G | P11: P2 | Q11: BTS | R11: BTS | S11: On Air | T11: Grid-Gen | U11: Roof Top | V11: RT | W11: Indoor | X11: Elvis Mumba | Y11: SBC | Z11: SBC | AA11: MTN | AB11: Mwenya Banda | AC11: GNM | AD11: GNM | AE11: IMG | AF11: IMG | AG11: 16 | AH11: perkins | AI11: 0 | AJ11: Leroy Sommer | AK11: 0 | AL11: 600 | AM11: Delta | AN11: DPS 2400B-48-5 | AO11: 250 | AP11: Lithium | AQ11: 400 | AR11: 48 | AS11: 100 | AT11: =AQ11/AS11 -> 4 | AU11: LG | AV11: LG | AW11: 18000 | AX11: 18000 | AY11: 2 | AZ11: 80 | BA11: 0 | BB11: 1 | BC11: MTN | BD11: T3024 | BE11: 0 | BF11: 0 | BH11: 0 | BI11: Palisade | BJ11: Inala | BK11: 44778 | BL11: No | BM11: No | BT11: No | BU11: No | BV11: No | BY11: n/a | BZ11: n/a | CB11: n/a | CG11: IHS_CBT_009M
A12: 488 | B12: T3084 | C12: IHS_CBT_010M | D12: Kabushi | E12: 28.628467 | F12: -13.001686 | G12: Copperbelt | H12: 2.5 | I12: COPPERBELT | J12: NDOLA | K12: No | L12: Yes | M12: No | N12: Suburban | O12: 2G 3G | P12: P1 | Q12: BTS | R12: BB | S12: On Air | T12: Grid-Gen | U12: Green Field | V12: 54 | W12: Indoor | X12: Elvis Mumba | Y12: SBC | Z12: SBC | AA12: MTN | AB12: Mwenya Banda | AC12: GNM | AD12: GNM | AE12: IMG | AF12: IMG | AG12: 15 | AH12: perkins | AI12: 0 | AJ12: Leroy Sommer | AK12: 0 | AL12: 600 | AM12: Power cube | AN12: ICC330-H1-C1 | AO12: 400 | AP12: Lithium | AQ12: 400 | AR12: 48 | AS12: 100 | AT12: =AQ12/AS12 -> 4 | AU12: LG | AV12: LG | AW12: 18000 | AX12: 18000 | AY12: 2 | AZ12: 125 | BA12: 0 | BB12: 1 | BC12: MTN | BD12: T3084 | BE12: 0 | BF12: yes | BH12: 0 | BI12: Palisade | BJ12: Inala | BK12: 44778 | BL12: No | BM12: No | BT12: No | BU12: No | BV12: No | BY12: n/a | BZ12: n/a | CB12: n/a | CG12: IHS_CBT_010M
A13: 1132 | B13: T3353 | C13: IHS_CBT_011M | D13: Monkey Mountain | E13: 28.60197 | F13: -12.97737 | G13: Copperbelt | H13: 2 | I13: COPPERBELT | J13: NDOLA | K13: Yes | L13: No | M13: No | N13: Urban | O13: 2G 3G | P13: P4 | Q13: BTS | R13: BTS | S13: On Air | T13: Grid-Gen | U13: Green Field | V13: 40 | W13: Outdoor | X13: Elvis Mumba | Y13: SBC | Z13: SBC | AA13: MTN | AB13: Mwenya Banda | AC13: GNM | AD13: GNM | AE13: Green Power | AF13: Green Power | AG13: 16 | AH13: perkins | AI13: 0 | AJ13: Mecc Alte | AK13: 0 | AL13: 600 | AM13: Power cube | AN13: ICC330-HA1-C10 | AO13: 250 | AP13: Power safe | AQ13: 1200 | AR13: 2 | AS13: 1200 | AT13: 24 | AU13: N/A | AV13: N/A | AW13: N/A | AX13: n/a | AY13: N/A | AZ13: 118 | BA13: 0 | BB13: 3 | BC13: MTNAirtelLiquid Telecom | BD13: T3353 | BE13: ZM0403 | BF13: yes | BH13: 0 | BI13: Palisade | BJ13: Inala | BK13: 44778 | BL13: No | BM13: No | BT13: No | BU13: No | BV13: No | BY13: n/a | BZ13: n/a | CB13: n/a | CG13: IHS_CBT_011M
A14: 440 | B14: T3354 | C14: IHS_CBT_012M | D14: Itawa West | E14: 28.65328 | F14: -12.98349 | G14: Copperbelt | H14: 2.5 | I14: COPPERBELT | J14: NDOLA | K14: No | L14: Yes | M14: No | N14: Urban | O14: 2G 3G | P14: P3 | Q14: BTS | R14: BTS | S14: On Air | T14: Grid-Gen | U14: Green Field | V14: 36 | W14: Outdoor | X14: Elvis Mumba | Y14: SBC | Z14: SBC | AA14: MTN | AB14: Mwenya Banda | AC14: GNM | AD14: GNM | AE14: Lamasat | AF14: Lamasat | AG14: 20 | AH14: perkins | AI14: 0 | AJ14: Leroy Sommer | AK14: 0 | AL14: 600 | AM14: Delta | AN14: DPS 2400B-48-5 | AO14: 250 | AP14: Wolong | AQ14: 600 | AR14: 2 | AS14: 600 | AT14: 24 | AU14: N/A | AV14: N/A | AW14: N/A | AX14: n/a | AY14: N/A | AZ14: 70 | BA14: 0 | BB14: 1 | BC14: MTN | BD14: T3354 | BE14: 0 | BF14: yes | BH14: 0 | BI14: Palisade | BJ14: Inala | BK14: 44778 | BL14: No | BM14: No | BT14: No | BU14: No | BV14: No | BY14: n/a | BZ14: n/a | CB14: n/a | CG14: IHS_CBT_012M
A15: 337 | B15: T3211 | C15: IHS_CBT_013M | D15: Dola Hill | E15: 28.6059 | F15: -12.95727 | G15: Copperbelt | H15: 4.5 | I15: COPPERBELT | J15: NDOLA | K15: Yes | L15: Yes | M15: No | N15: Urban | O15: 2G 3G 4G | P15: P3 | Q15: HUB | R15: BB | S15: On Air | T15: Grid-Gen | U15: Green Field | V15: 80 | W15: Indoor | X15: Elvis Mumba | Y15: SBC | Z15: SBC | AA15: MTN | AB15: Mwenya Banda | AC15: GNM | AD15: GNM | AE15: Himoinsa | AF15: Himoinsa | AG15: 30 | AH15: Yanmar | AI15: 4TNV | AJ15: HIMOINSA | AK15: SK 160 LB | AL15: 1000 | AM15: Power cube | AN15: ICC330-H1-C1 | AO15: 400 | AP15: Agisson | AQ15: 1200 | AR15: 2 | AS15: 600 | AT15: 48 | AU15: LG | AV15: LG | AW15: 18000 | AX15: 18000 | AY15: 2 | AZ15: 175 | BA15: 0 | BB15: 2 | BC15: MTNAirtel | BD15: T3211 | BE15: ZM3962 | BF15: yes | BH15: 0 | BI15: Palisade | BJ15: Inala | BK15: 44778 | BL15: No | BM15: No | BT15: No | BU15: No | BV15: No | BY15: n/a | BZ15: n/a | CB15: n/a | CG15: IHS_CBT_013M
A16: 870 | B16: T3201 | C16: IHS_CBT_014M | D16: Lubuto | E16: 28.61215 | F16: -13.00405 | G16: Copperbelt | H16: 2.5 | I16: COPPERBELT | J16: NDOLA | K16: Yes | L16: Yes | M16: No | N16: Suburban | O16: 2G 3G 4G | P16: P2 | Q16: BTS | R16: HUB | S16: On Air | T16: Grid-Gen | U16: Green Field | V16: 42 | W16: Indoor | X16: Elvis Mumba | Y16: SBC | Z16: SBC | AA16: MTN | AB16: Mwenya Banda | AC16: GNM | AD16: GNM | AE16: CK Works | AF16: CK Works | AG16: 20 | AH16: perkins | AI16: U 988804 C | AJ16: Leroy Sommer | AK16: 0 | AL16: 600 | AM16: Power cube | AN16: ICC330-H1-C1 | AO16: 400 | AP16: Lithium | AQ16: 500 | AR16: 48 | AS16: 100 | AT16: =AQ16/AS16 -> 5 | AU16: LG | AV16: LG | AW16: 18000 | AX16: 18000 | AY16: 2 | AZ16: 112 | BA16: 0 | BB16: 2 | BC16: MTNLiquid Telecom | BD16: T3201 | BE16: 0 | BF16: yes | BH16: 0 | BI16: Palisade | BJ16: Inala | BK16: 44778 | BL16: No | BM16: No | BT16: No | BU16: No | BV16: No | BY16: n/a | BZ16: n/a | CB16: n/a | CG16: IHS_CBT_014M
A17: 1786 | B17: T3055 | C17: IHS_CBT_015M | D17: Yengwe | E17: 28.648417 | F17: -12.94835 | G17: Copperbelt | H17: 2.5 | I17: COPPERBELT | J17: NDOLA | K17: Yes | L17: Yes | M17: No | N17: Urban | O17: 2G 3G 4G | P17: P2 | Q17: BTS | R17: BTS | S17: On Air | T17: Grid-Gen | U17: Green Field | V17: 36 | W17: Indoor | X17: Elvis Mumba | Y17: SBC | Z17: SBC | AA17: MTN | AB17: Mwenya Banda | AC17: GNM | AD17: GNM | AE17: CK Works | AF17: CK Works | AG17: 20 | AH17: perkins | AI17: 0 | AJ17: Leroy Sommer | AK17: 0 | AL17: 600 | AM17: Delta | AN17: DPS 2400B-48-5 | AO17: 250 | AP17: Power safe | AQ17: 1200 | AR17: 2 | AS17: 1200 | AT17: 24 | AU17: LG | AV17: LG | AW17: 18000 | AX17: 18000 | AY17: 2 | AZ17: 194 | BA17: 0 | BB17: 3 | BC17: MTNAirtelLiquid Telecom | BD17: T3055 | BE17: ZM6740 | BF17: yes | BH17: 0 | BI17: Palisade | BJ17: Inala | BK17: 44778 | BL17: No | BM17: No | BT17: No | BU17: No | BV17: No | BY17: n/a | BZ17: n/a | CB17: n/a | CG17: IHS_CBT_015M
A18: 439 | B18: T3083 | C18: IHS_CBT_016M | D18: Itawa | E18: 28.665111 | F18: -12.985314 | G18: Copperbelt | H18: 4.5 | I18: COPPERBELT | J18: NDOLA | K18: No | L18: Yes | M18: No | N18: Urban | O18: 2G 3G 4G | P18: P3 | Q18: BTS | R18: BB | S18: On Air | T18: Grid-Gen | U18: Green Field | V18: 54 | W18: Indoor | X18: Elvis Mumba | Y18: SBC | Z18: SBC | AA18: MTN | AB18: Mwenya Banda | AC18: GNM | AD18: GNM | AE18: Vitalgen | AF18: Vitalgen | AG18: 30 | AH18: perkins | AI18: 0 | AJ18: Leroy Sommer | AK18: 0 | AL18: 1000 | AM18: Power cube | AN18: ICC330-H1-C1 | AO18: 400 | AP18: Lithium | AQ18: 300 | AR18: 48 | AS18: 100 | AT18: =AQ18/AS18 -> 3 | AU18: LG | AV18: LG | AW18: 18000 | AX18: 18000 | AY18: 2 | AZ18: 117 | BA18: 0 | BB18: 2 | BC18: MTNAirtel | BD18: T3083 | BE18: ZM6838 | BF18: yes | BH18: 0 | BI18: Palisade | BJ18: Inala | BK18: 44778 | BL18: No | BM18: No | BT18: No | BU18: No | BV18: No | BY18: n/a | BZ18: n/a | CB18: n/a | CG18: IHS_CBT_016M
A19: 1516 | B19: T3324 | C19: IHS_CBT_017M | D19: Overspill | E19: 28.62691 | F19: -12.93633 | G19: Copperbelt | H19: 2.5 | I19: COPPERBELT | J19: NDOLA | K19: Yes | L19: Yes | M19: No | N19: Urban | O19: 2G 3G 4G | P19: P2 | Q19: BTS | R19: BTS | S19: On Air | T19: Grid-Gen | U19: Green Field | V19: 36 | W19: Outdoor | X19: Elvis Mumba | Y19: SBC | Z19: SBC | AA19: MTN | AB19: Mwenya Banda | AC19: GNM | AD19: GNM | AE19: Falcon | AF19: Falcon | AG19: 20 | AH19: perkins | AI19: GN66044U | AJ19: Leroy Sommer | AK19: 0 | AL19: 600 | AM19: Delta | AN19: DPS 2400B-48-5 | AO19: 250 | AP19: Lithium | AQ19: 200 | AR19: 48 | AS19: 100 | AT19: =AQ19/AS19 -> 2 | AU19: N/A | AV19: N/A | AW19: N/A | AX19: n/a | AY19: N/A | AZ19: 85 | BA19: 0 | BB19: 1 | BC19: MTN | BD19: T3324 | BE19: 0 | BF19: yes | BH19: 0 | BI19: Palisade | BJ19: Inala | BK19: 44778 | BL19: No | BM19: No | BT19: No | BU19: No | BV19: No | BY19: n/a | BZ19: n/a | CB19: n/a | CG19: IHS_CBT_017M
A20: 1474 | B20: T3204 | C20: IHS_CBT_018M | D20: Nkwanzi | E20: 28.64032 | F20: -12.93674 | G20: Copperbelt | H20: 2.5 | I20: COPPERBELT | J20: NDOLA | K20: Yes | L20: Yes | M20: No | N20: Suburban | O20: 2G 3G | P20: P2 | Q20: BTS | R20: HUB | S20: On Air | T20: Grid-Gen | U20: Green Field | V20: 42 | W20: Indoor | X20: Elvis Mumba | Y20: SBC | Z20: SBC | AA20: MTN | AB20: Mwenya Banda | AC20: GNM | AD20: GNM | AE20: CK Works | AF20: CK Works | AG20: 20 | AH20: perkins | AI20: 0 | AJ20: Leroy Sommer | AK20: 0 | AL20: 600 | AM20: Delta | AN20: DPS 2400B-48-5 | AO20: 250 | AP20: Lithium | AQ20: 400 | AR20: 48 | AS20: 100 | AT20: =AQ20/AS20 -> 4 | AU20: LG | AV20: LG | AW20: 18000 | AX20: 18000 | AY20: 2 | AZ20: 138 | BA20: 0 | BB20: 2 | BC20: MTNAirtel | BD20: T3204 | BE20: ZM6785 | BF20: 0 | BH20: 0 | BI20: Palisade | BJ20: Inala | BK20: 44778 | BL20: No | BM20: No | BT20: No | BU20: No | BV20: No | BY20: n/a | BZ20: n/a | CB20: n/a | CG20: IHS_CBT_018M
A21: 1288 | B21: T3203 | C21: IHS_CBT_020M | D21: Mushili | E21: 28.63052 | F21: -13.01879 | G21: Copperbelt | H21: 4.5 | I21: COPPERBELT | J21: NDOLA | K21: No | L21: Yes | M21: No | N21: Suburban | O21: 2G 3G | P21: P2 | Q21: BTS | R21: BTS | S21: On Air | T21: Grid-Gen | U21: Green Field | V21: 36 | W21: Indoor | X21: Elvis Mumba | Y21: SBC | Z21: SBC | AA21: MTN | AB21: Mwenya Banda | AC21: GNM | AD21: GNM | AE21: CK Works | AF21: CK Works | AG21: 30 | AH21: perkins | AI21: 0 | AJ21: Leroy Sommer | AK21: 0 | AL21: 1000 | AM21: Power cube | AN21: ICC330-HA1-C10 | AO21: 750 | AP21: Lithium | AQ21: 400 | AR21: 48 | AS21: 100 | AT21: =AQ21/AS21 -> 4 | AU21: LG | AV21: LG | AW21: 18000 | AX21: 18000 | AY21: 2 | AZ21: 144 | BA21: 0 | BB21: 2 | BC21: MTNAirtel | BD21: T3203 | BE21: ZM3468 | BF21: yes | BH21: 0 | BI21: Palisade | BJ21: Inala | BK21: 44778 | BL21: No | BM21: No | BT21: No | BU21: No | BV21: No | BY21: n/a | BZ21: n/a | CB21: n/a | CG21: IHS_CBT_020M
A22: 1669 | B22: T3229 | C22: IHS_CBT_021M | D22: Sky ways | E22: 28.6 | F22: -13.00924 | G22: Copperbelt | H22: 2.5 | I22: COPPERBELT | J22: NDOLA | K22: No | L22: No | M22: No | N22: Urban | O22: 2G 3G | P22: P4 | Q22: BTS | R22: BTS | S22: On Air | T22: Grid-Gen | U22: Green Field | V22: 36 | W22: Indoor | X22: Elvis Mumba | Y22: SBC | Z22: SBC | AA22: MTN | AB22: Mwenya Banda | AC22: GNM | AD22: GNM | AE22: CK Works | AF22: CK Works | AG22: 20 | AH22: perkins | AI22: 0 | AJ22: Mecc Alte | AK22: 0 | AL22: 1000 | AM22: Power cube | AN22: ICC330-H1-C1 | AO22: 400 | AP22: Lithium | AQ22: 400 | AR22: 48 | AS22: 100 | AT22: =AQ22/AS22 -> 4 | AU22: LG | AV22: LG | AW22: 18000 | AX22: 18000 | AY22: 2 | AZ22: 126 | BA22: 0 | BB22: 4 | BC22: MTNAirtelINQLiquid Telecom | BD22: T3229 | BE22: ZM6582 | BF22: 0 | BH22: 0 | BI22: Palisade | BJ22: Inala | BK22: 44778 | BL22: No | BM22: No | BT22: No | BU22: No | BV22: Yes | BY22: yes | BZ22: 20 | CB22: Pending | CG22: IHS_CBT_021M
A23: 694 | B23: T3077 | C23: IHS_CBT_022M | D23: Kasembo | E23: 28.643861 | F23: -13.016333 | G23: Copperbelt | H23: 2.5 | I23: COPPERBELT | J23: NDOLA | K23: Yes | L23: Yes | M23: No | N23: Suburban | O23: 2G 3G 4G | P23: P2 | Q23: BTS | R23: BTS | S23: On Air | T23: Grid-Gen | U23: Green Field | V23: 50 | W23: Indoor | X23: Elvis Mumba | Y23: SBC | Z23: SBC | AA23: MTN | AB23: Mwenya Banda | AC23: GNM | AD23: GNM | AE23: Gen Logic | AF23: Gen Logic | AG23: 20 | AH23: perkins | AI23: 0 | AJ23: Leroy Sommer | AK23: 0 | AL23: 1000 | AM23: Delta | AN23: DPS 2400B-48-5 | AO23: 250 | AP23: Lithium | AQ23: 500 | AR23: 48 | AS23: 100 | AT23: =AQ23/AS23 -> 5 | AU23: LG | AV23: LG | AW23: 18000 | AX23: 18000 | AY23: 2 | AZ23: 125 | BA23: 0 | BB23: 3 | BC23: MTNAirtelLiquid Telecom | BD23: T3077 | BE23: ZM3293 | BF23: 0 | BH23: 0 | BI23: Palisade | BJ23: Inala | BK23: 44778 | BL23: No | BM23: No | BT23: No | BU23: No | BV23: No | BY23: n/a | BZ23: n/a | CB23: n/a | CG23: IHS_CBT_022M
A24: 1750 | B24: T3054 | C24: IHS_CBT_023M | D24: Twapia | E24: 28.583483 | F24: -12.9855 | G24: Copperbelt | H24: 1.8 | I24: COPPERBELT | J24: NDOLA | K24: No | L24: No | M24: No | N24: Suburban | O24: 2G 3G | P24: P3 | Q24: BTS | R24: BTS | S24: On Air | T24: Grid-Gen | U24: Green Field | V24: 50 | W24: Indoor | X24: Elvis Mumba | Y24: SBC | Z24: SBC | AA24: MTN | AB24: Mwenya Banda | AC24: GNM | AD24: GNM | AE24: Gen Logic | AF24: Gen Logic | AG24: 15 | AH24: perkins | AI24: 0 | AJ24: Mecc Alte | AK24: 0 | AL24: 1000 | AM24: Delta | AN24: DPS 2400B-48-5 | AO24: 250 | AP24: Lithium | AQ24: 500 | AR24: 48 | AS24: 100 | AT24: =AQ24/AS24 -> 5 | AU24: LG | AV24: LG | AW24: 18000 | AX24: 18000 | AY24: 2 | AZ24: 51 | BA24: 0 | BB24: 1 | BC24: MTN | BD24: T3054 | BE24: 0 | BF24: yes | BH24: 0 | BI24: Palisade | BJ24: Inala | BK24: 44778 | BL24: No | BM24: No | BT24: No | BU24: No | BV24: No | BY24: n/a | BZ24: n/a | CB24: n/a | CG24: IHS_CBT_023M
A25: 1409 | B25: T3233 | C25: IHS_CBT_024M | D25: Ndeke Township | E25: 28.66315 | F25: -13.006631 | G25: Copperbelt | H25: 4.5 | I25: COPPERBELT | J25: NDOLA | K25: No | L25: Yes | M25: No | N25: Suburban | O25: 2G 3G | P25: P2 | Q25: BTS | R25: BB | S25: On Air | T25: Grid-Gen | U25: Green Field | V25: 30 | W25: Indoor | X25: Elvis Mumba | Y25: SBC | Z25: SBC | AA25: MTN | AB25: Mwenya Banda | AC25: GNM | AD25: GNM | AE25: CK Works | AF25: CK Works | AG25: 30 | AH25: perkins | AI25: 0 | AJ25: Leroy Sommer | AK25: 0 | AL25: 600 | AM25: Power cube | AN25: ICC330-H1-C1 | AO25: 400 | AP25: Lithium | AQ25: 500 | AR25: 48 | AS25: 100 | AT25: =AQ25/AS25 -> 5 | AU25: LG | AV25: LG | AW25: 18000 | AX25: 18000 | AY25: 2 | AZ25: 185 | BA25: 0 | BB25: 2 | BC25: MTNAirtel | BD25: T3233 | BE25: ZM6959 | BF25: yes | BH25: 0 | BI25: Palisade | BJ25: Inala | BK25: 44778 | BL25: No | BM25: No | BT25: No | BU25: No | BV25: No | BY25: n/a | BZ25: n/a | CB25: n/a | CG25: IHS_CBT_024M
A26: 1520 | B26: T3205 | C26: IHS_CBT_025M | D26: Pamozi Extension | E26: 28.62378 | F26: -12.92625 | G26: Copperbelt | H26: 2 | I26: COPPERBELT | J26: NDOLA | K26: Yes | L26: Yes | M26: No | N26: Suburban | O26: 2G 3G 4G | P26: P2 | Q26: BTS | R26: BTS | S26: On Air | T26: Grid-Gen | U26: Green Field | V26: 36 | W26: Indoor | X26: Elvis Mumba | Y26: SBC | Z26: SBC | AA26: MTN | AB26: Mwenya Banda | AC26: GNM | AD26: GNM | AE26: GL Yanmar | AF26: GL Yanmar | AG26: 16 | AH26: Yanmar | AI26: 4TNE | AJ26: Mecc Alte | AK26: 0 | AL26: 600 | AM26: Power cube | AN26: ICC330-HA1-C10 | AO26: 250 | AP26: Lithium | AQ26: 300 | AR26: 48 | AS26: 100 | AT26: =AQ26/AS26 -> 3 | AU26: LG | AV26: LG | AW26: 18000 | AX26: 18000 | AY26: 2 | AZ26: 72.4 | BA26: 0 | BB26: 1 | BC26: MTN | BD26: T3205 | BE26: 0 | BF26: yes | BH26: 0 | BI26: Palisade | BJ26: Inala | BK26: 44778 | BL26: No | BM26: No | BT26: No | BU26: No | BV26: No | BY26: n/a | BZ26: n/a | CB26: n/a | CG26: IHS_CBT_025M
A27: 634 | B27: T3351 | C27: IHS_CBT_027M | D27: Kantolomba | E27: 28.63368 | F27: -13.02945 | G27: Copperbelt | H27: 2.5 | I27: COPPERBELT | J27: NDOLA | K27: No | L27: Yes | M27: No | N27: Suburban | O27: 2G 3G | P27: P2 | Q27: BTS | R27: BTS | S27: On Air | T27: Grid-Gen | U27: Green Field | V27: 30 | W27: Outdoor | X27: Elvis Mumba | Y27: SBC | Z27: SBC | AA27: MTN | AB27: Mwenya Banda | AC27: GNM | AD27: GNM | AE27: CK Works | AF27: CK Works | AG27: 20 | AH27: perkins | AI27: 0 | AJ27: Leroy Sommer | AK27: 0 | AL27: 600 | AM27: Delta | AN27: DPS 2400B-48-5 | AO27: 250 | AP27: NARADA | AQ27: 600 | AR27: 2 | AS27: 600 | AT27: 24 | AU27: N/A | AV27: N/A | AW27: N/A | AX27: n/a | AY27: N/A | AZ27: 154 | BA27: 0 | BB27: 2 | BC27: MTNAirtel | BD27: T3351 | BE27: ZM0237 | BF27: yes | BH27: 0 | BI27: Palisade | BJ27: Inala | BK27: 44778 | BL27: No | BM27: No | BT27: No | BU27: No | BV27: No | BY27: n/a | BZ27: n/a | CB27: n/a | CG27: IHS_CBT_027M
A28: 1788 | B28: T3355 | C28: IHS_CBT_029M | D28: Zafico | E28: 28.56954 | F28: -12.97282 | G28: Copperbelt | H28: 1.8 | I28: COPPERBELT | J28: NDOLA | K28: No | L28: No | M28: No | N28: Suburban | O28: 2G 3G | P28: P4 | Q28: BTS | R28: BTS | S28: On Air | T28: Grid-Gen | U28: Green Field | V28: 36 | W28: Outdoor | X28: Elvis Mumba | Y28: SBC | Z28: SBC | AA28: MTN | AB28: Mwenya Banda | AC28: GNM | AD28: GNM | AE28: Green Power | AF28: Green Power | AG28: 15 | AH28: perkins | AI28: 0 | AJ28: Mecc Alte | AK28: 0 | AL28: 600 | AM28: Delta | AN28: DPS 2400B-48-5 | AO28: 250 | AP28: Agisson | AQ28: 600 | AR28: 2 | AS28: 600 | AT28: 24 | AU28: N/A | AV28: N/A | AW28: N/A | AX28: n/a | AY28: N/A | AZ28: 56 | BA28: 0 | BB28: 2 | BC28: MTNAirtel | BD28: T3355 | BE28: ZM6868 | BF28: 0 | BH28: 0 | BI28: Palisade | BJ28: Inala | BK28: 44778 | BL28: No | BM28: No | BT28: No | BU28: No | BV28: No | BY28: n/a | BZ28: n/a | CB28: n/a | CG28: IHS_CBT_029M
A29: 1416 | B29: T3274 | C29: IHS_CBT_030M | D29: Ndola Industrial | E29: 28.66418 | F29: -13.02343 | G29: Copperbelt | H29: 2.5 | I29: COPPERBELT | J29: NDOLA | K29: Yes | L29: No | M29: No | N29: Suburban | O29: 2G 3G | P29: P4 | Q29: BTS | R29: BTS | S29: On Air | T29: Grid-Gen | U29: Green Field | V29: 36 | W29: Outdoor | X29: Elvis Mumba | Y29: SBC | Z29: SBC | AA29: MTN | AB29: Mwenya Banda | AC29: GNM | AD29: GNM | AE29: MPI | AF29: MPI | AG29: 20 | AH29: perkins | AI29: 0 | AJ29: Leroy Sommer | AK29: 0 | AL29: 600 | AM29: Power cube | AN29: ICC330-H1-C1 | AO29: 400 | AP29: Agisson | AQ29: 1200 | AR29: 2 | AS29: 600 | AT29: 48 | AU29: N/A | AV29: N/A | AW29: N/A | AX29: n/a | AY29: N/A | AZ29: 89 | BA29: 0 | BB29: 1 | BC29: MTN | BD29: T3274 | BE29: 0 | BF29: yes | BH29: 0 | BI29: Palisade | BJ29: Inala | BK29: 44778 | BL29: No | BM29: No | BT29: No | BU29: No | BV29: No | BY29: n/a | BZ29: n/a | CB29: n/a | CG29: IHS_CBT_030M
A30: 745 | B30: T3102 | C30: IHS_CBT_031M | D30: Kawama | E30: 28.618658 | F30: -12.916144 | G30: Copperbelt | H30: 2 | I30: COPPERBELT | J30: NDOLA | K30: No | L30: Yes | M30: No | N30: Suburban | O30: 2G 3G | P30: P3 | Q30: BTS | R30: BTS | S30: On Air | T30: Grid-Gen | U30: Green Field | V30: 48 | W30: Indoor | X30: Elvis Mumba | Y30: SBC | Z30: SBC | AA30: MTN | AB30: Mwenya Banda | AC30: GNM | AD30: GNM | AE30: GL Yanmar | AF30: GL Yanmar | AG30: 20 | AH30: Yanmar | AI30: 4TNE | AJ30: Mecc Alte | AK30: 0 | AL30: 600 | AM30: Delta | AN30: DPS 2400B-48-5 | AO30: 250 | AP30: C&D True | AQ30: 704 | AR30: 12 | AS30: 176 | AT30: 16 | AU30: LG | AV30: LG | AW30: 18000 | AX30: 18000 | AY30: 2 | AZ30: 48.6 | BA30: 0 | BB30: 1 | BC30: MTN | BD30: T3102 | BE30: 0 | BF30: 0 | BH30: 0 | BI30: Palisade | BJ30: Inala | BK30: 44778 | BL30: No | BM30: No | BT30: No | BU30: No | BV30: No | BY30: n/a | BZ30: n/a | CB30: n/a | CG30: IHS_CBT_031M
A31: 314 | B31: T3197 | C31: IHS_CBT_032M | D31: Cleveland | E31: 28.69061 | F31: -12.97832 | G31: Copperbelt | H31: 2.5 | I31: COPPERBELT | J31: NDOLA | K31: No | L31: No | M31: No | N31: Suburban | O31: 2G 3G | P31: P4 | Q31: BTS | R31: HUB | S31: On Air | T31: Grid-Gen | U31: Green Field | V31: 42 | W31: Indoor | X31: Elvis Mumba | Y31: SBC | Z31: SBC | AA31: MTN | AB31: Mwenya Banda | AC31: GNM | AD31: GNM | AE31: CK Works | AF31: CK Works | AG31: 20 | AH31: perkins | AI31: 0 | AJ31: Leroy Sommer | AK31: 0 | AL31: 600 | AM31: Delta | AN31: DPS 2400B-48-5 | AO31: 250 | AP31: Lithium | AQ31: 300 | AR31: 48 | AS31: 100 | AT31: =AQ31/AS31 -> 3 | AU31: LG | AV31: LG | AW31: 18000 | AX31: 18000 | AY31: 2 | AZ31: 50 | BA31: 0 | BB31: 2 | BC31: MTNAirtel | BD31: T3197 | BE31: ZM3966 | BF31: yes | BH31: 0 | BI31: Palisade | BJ31: Inala | BK31: 44778 | BL31: Yes | BM31: Yes | BR31: pending | BT31: No | BU31: No | BV31: No | BY31: n/a | BZ31: n/a | CB31: n/a | CG31: IHS_CBT_032M
A32: 58 | B32: T3209 | C32: IHS_CBT_033M | D32: Bwana Mukubwa | E32: 28.69584 | F32: -13.01751 | G32: Copperbelt | H32: 2 | I32: COPPERBELT | J32: NDOLA | K32: No | L32: No | M32: No | N32: Suburban | O32: 2G 3G | P32: P4 | Q32: BTS | R32: HUB | S32: On Air | T32: Grid-Gen | U32: Green Field | V32: 36 | W32: Indoor | X32: Elvis Mumba | Y32: SBC | Z32: SBC | AA32: MTN | AB32: Mwenya Banda | AC32: GNM | AD32: GNM | AE32: GL Yanmar | AF32: GL Yanmar | AG32: 16 | AH32: Yanmar | AI32: 4TNE | AJ32: Mecc Alte | AK32: 0 | AL32: 600 | AM32: Delta | AN32: DPS 2400B-48-5 | AO32: 250 | AP32: Lithium | AQ32: 300 | AR32: 48 | AS32: 100 | AT32: =AQ32/AS32 -> 3 | AU32: LG | AV32: LG | AW32: 18000 | AX32: 18000 | AY32: 2 | AZ32: 56.7 | BA32: 0 | BB32: 2 | BC32: MTNAirtel | BD32: T3209 | BE32: ZM6730 | BF32: 0 | BH32: 0 | BI32: Palisade | BJ32: Inala | BK32: 44778 | BL32: No | BM32: No | BT32: No | BU32: No | BV32: No | BY32: n/a | BZ32: n/a | CB32: n/a | CG32: IHS_CBT_033M
A33: 1289 | B33: T3199 | C33: IHS_CBT_034M | D33: Mushili Baracks | E33: 28.623211 | F33: -13.056081 | G33: Copperbelt | H33: 1.8 | I33: COPPERBELT | J33: NDOLA | K33: No | L33: No | M33: No | N33: Suburban | O33: 2G 3G | P33: P4 | Q33: BTS | R33: Hub | S33: On Air | T33: Grid-Gen | U33: Green Field | V33: 48 | W33: Indoor | X33: Elvis Mumba | Y33: SBC | Z33: SBC | AA33: MTN | AB33: Mwenya Banda | AC33: GNM | AD33: GNM | AE33: GL Yanmar | AF33: GL Yanmar | AG33: 15 | AH33: Yanmar | AI33: 4TNE | AJ33: Mecc Alte | AK33: 0 | AL33: 600 | AM33: Delta | AN33: DPS 2400B-48-5 | AO33: 250 | AP33: NARADA | AQ33: 600 | AR33: 2 | AS33: 600 | AT33: 24 | AU33: LG | AV33: LG | AW33: 18000 | AX33: 18000 | AY33: 2 | AZ33: 48.7 | BA33: 0 | BB33: 1 | BC33: MTN | BD33: T3199 | BE33: 0 | BF33: yes | BH33: 0 | BI33: Palisade | BJ33: Inala | BK33: 44778 | BL33: No | BM33: No | BT33: No | BU33: No | BV33: No | BY33: n/a | BZ33: n/a | CB33: n/a | CG33: IHS_CBT_034M
A34: 555 | B34: T3005 | C34: IHS_CBT_035M | D34: Kaloko | E34: 28.67233 | F34: -13.04833 | G34: Copperbelt | H34: 4.5 | I34: COPPERBELT | J34: NDOLA | K34: Yes | L34: Yes | M34: No | N34: Suburban | O34: 2G 3G 4G | P34: P2 | Q34: BB | R34: Hub | S34: On Air | T34: Grid-Gen | U34: Green Field | V34: 60 | W34: Indoor | X34: Elvis Mumba | Y34: SBC | Z34: SBC | AA34: MTN | AB34: Mwenya Banda | AC34: GNM | AD34: GNM | AE34: Himoinsa | AF34: Himoinsa | AG34: 30 | AH34: Yanmar | AI34: 4TNV | AJ34: HIMOINSA | AK34: SK 160 LB | AL34: 1000 | AM34: Power cube | AN34: ICC330-H1-C1 | AO34: 400 | AP34: Lithium | AQ34: 600 | AR34: 48 | AS34: 100 | AT34: =AQ34/AS34 -> 6 | AU34: LG | AV34: LG | AW34: 18000 | AX34: 18000 | AY34: 2 | AZ34: 160 | BA34: 0 | BB34: 6 | BC34: MTNLiquid( Former Hai)Paratus TelecomGo tvKNCAir-link | BD34: T3005 | BE34: 0 | BF34: 0 | BH34: 0 | BI34: Palisade | BJ34: Inala | BK34: 44778 | BL34: No | BM34: No | BT34: No | BU34: No | BV34: No | BY34: n/a | BZ34: n/a | CB34: n/a | CG34: IHS_CBT_035M
A35: 863 | B35: T3208 | C35: IHS_CBT_036M | D35: Lubendo | E35: 28.710531 | F35: -12.94999 | G35: Copperbelt | H35: 2 | I35: COPPERBELT | J35: NDOLA | K35: Yes | L35: No | M35: No | N35: Rural | O35: #N/A | P35: P4 | Q35: BTS | R35: BTS | S35: On Air | T35: Grid-Gen | U35: Green Field | V35: 36 | W35: Indoor | X35: Elvis Mumba | Y35: SBC | Z35: SBC | AA35: MTN | AB35: Mwenya Banda | AC35: GNM | AD35: GNM | AE35: GL Yanmar | AF35: GL Yanmar | AG35: 16 | AH35: Yanmar | AI35: 4TNE | AJ35: Mecc Alte | AK35: 0 | AL35: 600 | AM35: Delta | AN35: DPS 2400B-48-5 | AO35: 250 | AP35: Amaron | AQ35: 600 | AR35: 2 | AS35: 600 | AT35: 24 | AU35: LG | AV35: LG | AW35: 18000 | AX35: 18000 | AY35: 2 | AZ35: 45 | BA35: 0 | BB35: 1 | BC35: Airtel | BD35: T3208 | BE35: ZM6590 | BF35: 0 | BH35: 0 | BI35: Palisade | BJ35: Inala | BK35: 44778 | BL35: No | BM35: No | BT35: No | BU35: No | BV35: No | BY35: n/a | BZ35: n/a | CB35: n/a | CG35: IHS_CBT_036M
A36: 1111 | B36: T3207 | C36: IHS_CBT_037M | D36: Minsundu | E36: 28.63172 | F36: -12.87315 | G36: Copperbelt | H36: 2 | I36: COPPERBELT | J36: NDOLA | K36: No | L36: No | M36: No | N36: Rural | O36: 2G 3G | P36: P4 | Q36: BTS | R36: BTS | S36: On Air | T36: Grid-Gen | U36: Green Field | V36: 70 | W36: Indoor | X36: Elvis Mumba | Y36: SBC | Z36: SBC | AA36: MTN | AB36: Mwenya Banda | AC36: GNM | AD36: GNM | AE36: GL Yanmar | AF36: GL Yanmar | AG36: 16 | AH36: Yanmar | AI36: 4TNE | AJ36: Mecc Alte | AK36: 0 | AL36: 600 | AM36: Delta | AN36: DPS 2400B-48-5 | AO36: 250 | AP36: Power safe | AQ36: 1200 | AR36: 2 | AS36: 1200 | AT36: 24 | AU36: LG | AV36: LG | AW36: 18000 | AX36: 18000 | AY36: 2 | AZ36: 96.6 | BA36: 0 | BB36: 2 | BC36: MTNAirtel | BD36: T3207 | BE36: ZM3964 | BF36: 0 | BH36: 0 | BI36: Palisade | BJ36: Inala | BK36: 44778 | BL36: No | BM36: No | BT36: No | BU36: No | BV36: No | BY36: n/a | BZ36: n/a | CB36: n/a | CG36: IHS_CBT_037M
